Workbook

Sheet 안내
B2: 이격거리 조례 검토표
B3: 전남 22개 시군 도시계획 조례의 발전시설 이격거리 조항 · 2026-09-18 작성
B5: 이 표의 목적
B6: 무엇을 | C6: 조례 원문에서 기계로 뽑아낸 이격거리 '후보'를 사람이 원문과 대조해 확정합니다. 확정한 값만 판정 시스템(data/setback_table.csv)에 들어갑니다.
B7: 왜 사람이 | C7: 조례 해석은 법령 판단이라 기계가 대신할 수 없습니다. 추출 후보는 검토를 빠르게 하기 위한 보조일 뿐이며, 틀릴 수 있습니다. 반드시 K열 원문과 대조해 주세요.
B9: 작성 방법
B10: 노란 칸만 채웁니다 | C10: M~S열(노란색)만 입력합니다. 나머지 열은 원문에서 가져온 참고값이라 수정하지 않습니다.
B11: 1. 원문 확인 | C11: K열 원문을 읽고, F·G열 후보값이 맞는지 봅니다. L열 링크로 조례 전문을 열 수 있습니다.
B12: 2. 값 확정 | C12: M열 확정 거리(m), N열 밀집 기준 호수를 입력합니다. 후보가 맞으면 같은 값을 그대로 적습니다. T열이 '일치/변경'을 자동으로 보여줍니다.
B13: 3. 반영 여부 | C13: P열에 Y(판정에 반영) 또는 N(반영 안 함)을 고릅니다. 예외 조항이거나 이격거리가 아닌 행은 N.
B14: 4. 서명 | C14: Q열 검토자, R열 검토일을 적습니다. 검토자가 비어 있는 행은 시스템이 무시합니다.
B16: 꼭 봐야 하는 행
B17: 주황색 행 | C17: H열에 사유가 적힌 행입니다. 한 줄에 거리가 여러 개(예: '10호 미만은 300미터')이거나 '다만/예외/동의' 단서가 붙어 있어 후보값이 틀렸을 가능성이 높습니다.
B18: '직접 확인 필요' 시트 | C18: 조문을 찾지 못했거나(고흥·장흥·강진·영광) 구조가 달라 추출이 안 된(나주) 5개 시군입니다. 조례 전문을 직접 확인해야 합니다.
B20: 기대 효과 (중요)
B21: 표를 다 채우면 | C21: 근거 조문이 정확해지고, 아래 두 경우는 실제 판정이 나옵니다. · 조례에 이격 규정이 '없다'고 확인된 시군 → 비저촉 · 개발행위허가 신청일이 2026-09-18 이전 → 조건부(종전 조례 적용)
B22: 그래도 남는 것 | C22: 2026-09-18 이후 신청분 대부분은 여전히 '판정불가'입니다. 「신재생에너지법」 제27조의3에 따라 역사문화환경보존지역·생태경관보전지역 해당 여부를 알아야 판단할 수 있는데, 그 판별이 아직 자동화되지 않았기 때문입니다. 이 표를 채우는 것만으로는 해결되지 않습니다.
B24: 입력 예시
B25: 예시 (목포시 도로) | C25: F 후보 100 → M 확정 100, N 비움, O 2020-08-10(1호 개정일), P Y, Q 서장훈, R 2026-09-20 ※ 예시는 이 시트에만 있습니다. 검토표에 가짜 확정값을 넣지 않은 것은, 그 행이 실수로 판정 시스템에 들어가면 사람이 확인하지 않은 값이 확정값처럼 쓰이기 때문입니다.

Sheet 검토표
A1: 이격거리 조례 검토표
A2: 노란 칸(M~S열)만 입력합니다 · 주황색 행은 후보값이 틀렸을 가능성이 높아 원문을 꼭 확인하세요 · 검토자가 비어 있는 행은 판정에 쓰이지 않습니다
A3: 번호 | B3: 시군구 | C3: 시군구코드 | D3: 사업유형 | E3: 대상 | F3: 추출 거리(m) [후보] | G3: 추출 호수 [후보] | H3: 확인 필요 | I3: 조례명 | J3: 조문 | K3: 원문 (해당 호) | L3: 조례 전문 | M3: 확정 거리(m) | N3: 확정 호수 | O3: 고시일 | P3: 판정 반영 (Y/N) | Q3: 검토자 | R3: 검토일 | S3: 검토 메모 | T3: 후보와 비교
A4: 1 | B4: 목포시 | C4: 12110 | D4: 태양광 | E4: 관광지 | F4: 100 | I4: 목포시 도시계획 조례 | J4: 제17조의4 | K4: 5. 「관광진흥법」에 따른 관광지 및 관광단지 경계로부터 100미터 안에 입지하지 아니할 것. | L4: 열기 | T4: =IF(M4="","",IF(M4=F4,"일치","변경"))
A5: 2 | B5: 목포시 | C5: 12110 | D5: 태양광 | E5: 도로 | F5: 100 | H5: 한 줄에 거리 여러 개 | I5: 목포시 도시계획 조례 | J5: 제17조의4 | K5: 1. 「도로법」이 적용되는 도로(국도, 지방도, 시도 등 2차선 또는 폭 6미터 이상의 포장도로) 경계로부터 100미터 안에 입지하지 아니할 것. <개정 2018.12.17., 2020.8.10.> | L5: 열기 | T5: =IF(M5="","",IF(M5=F5,"일치","변경"))
A6: 3 | B6: 목포시 | C6: 12110 | D6: 태양광 | E6: 문화유산 | F6: 100 | I6: 목포시 도시계획 조례 | J6: 제17조의4 | K6: 6. 「문화유산보존 및 활용에 관한 법률」의 적용을 받는 문화유산 부지 경계로부터 100미터 안에 입지하지 아니할 것. | L6: 열기 | T6: =IF(M6="","",IF(M6=F6,"일치","변경"))
A7: 4 | B7: 목포시 | C7: 12110 | D7: 태양광 | E7: 자연취락지구 | F7: 100 | I7: 목포시 도시계획 조례 | J7: 제17조의4 | K7: 3. 자연취락지구 경계로부터 100미터 안에 입지하지 아니할 것. | L7: 열기 | T7: =IF(M7="","",IF(M7=F7,"일치","변경"))
A8: 5 | B8: 목포시 | C8: 12110 | D8: 태양광 | E8: 주거밀집지역 | F8: 100 | G8: 10 | I8: 목포시 도시계획 조례 | J8: 제17조의4 | K8: 2. 주거밀집지역(10호 이상의 실제 주민이 거주하는 인가가 밀집된 지역) 경계로부터 100미터 안에 입지하지 아니할 것. | L8: 열기 | T8: =IF(M8="","",IF(M8=F8,"일치","변경"))
A9: 6 | B9: 여수시 | C9: 12130 | D9: 풍력 | E9: 가축사육시설 | F9: 1500 | I9: 여수시 도시계획 조례 | J9: 제12조의2 | K9: 라.「축산법」에 따른 가축 사육시설 및 육상 축양장 등 생산시설 부지경계에서 1,500미터 이내에 입지하지 아니할 것 | L9: 열기 | T9: =IF(M9="","",IF(M9=F9,"일치","변경"))
A10: 7 | B10: 여수시 | C10: 12130 | D10: 풍력 | E10: 도로 | F10: 300 | I10: 여수시 도시계획 조례 | J10: 제12조의2 | K10: 가. 도로 및 철도 부지경계에서 직선거리 300미터 이내에 입지하지 아니할 것 | L10: 열기 | T10: =IF(M10="","",IF(M10=F10,"일치","변경"))
A11: 8 | B11: 여수시 | C11: 12130 | D11: 풍력 | E11: 도로 | F11: 200 | I11: 여수시 도시계획 조례 | J11: 제12조의2 | K11: 가. 도로 및 철도, 하천, 저수지 부지경계에서 직선거리 200미터 이내에 입지하지 아니할 것 | L11: 열기 | T11: =IF(M11="","",IF(M11=F11,"일치","변경"))
A12: 9 | B12: 여수시 | C12: 12130 | D12: 풍력 | E12: 도로 | F12: 100 | I12: 여수시 도시계획 조례 | J12: 제12조의2 | K12: 가. 도로 및 철도, 하천, 저수지 부지경계에서 직선거리 100미터 이내에 입지하지 아니할 것 | L12: 열기 | T12: =IF(M12="","",IF(M12=F12,"일치","변경"))
A13: 10 | B13: 여수시 | C13: 12130 | D13: 풍력 | E13: 정온시설 | F13: 1500 | I13: 여수시 도시계획 조례 | J13: 제12조의2 | K13: 나. 정온시설(초·중·고등학교, 대학교, 도서관, 노인요양시설, 유치원, 병원, 경로당 등 기타 유사한 시설로서 시장이 인정한 경우) 부지경계에서 1,500미터 이내에 입지하지 아니할 것 | L13: 열기 | T13: =IF(M13="","",IF(M13=F13,"일치","변경"))
A14: 11 | B14: 여수시 | C14: 12130 | D14: 풍력 | E14: 주거밀집지역 | F14: 2000 | G14: 10 | H14: 한 줄에 거리 여러 개 / 다만·예외·동의 단서 | I14: 여수시 도시계획 조례 | J14: 제12조의2 | K14: 나. 주거밀집지역(10호 이상의 실제 주민이 거주하는 인가가 밀집된 지역을 말하며, 주택과 주택사이의 직선거리가 50미터 이내로 연결되는 호수를 합산) 주택 부지 경계에서 직선거리 2,000미터 이내에 입지하지 아니할 것. (10호 미만 주거밀집지역은 주택부지 경계에서 직선거리 1,000미터 이내에 입지하지 아니할 것.) 단, 해당 지역에 거주하는 주민등록상 세대주의 90% 이상 동의를 얻은 경우 허용할 수 있다. | L14: 열기 | T14: =IF(M14="","",IF(M14=F14,"일치","변경"))
A15: 12 | B15: 여수시 | C15: 12130 | D15: 풍력 | E15: 주택 | F15: 1500 | I15: 여수시 도시계획 조례 | J15: 제12조의2 | K15: 다. 주민이 실제 거주하는 주택 부지경계에서 1,500미터 이내에 입지하지 아니할 것 | L15: 열기 | T15: =IF(M15="","",IF(M15=F15,"일치","변경"))
A16: 13 | B16: 여수시 | C16: 12130 | D16: 풍력 | E16: 주택 | F16: 500 | I16: 여수시 도시계획 조례 | J16: 제12조의2 | K16: 나. 주민이 실제 거주하는 주택 부지경계에서 500미터 이내에 입지하지 아니할 것 | L16: 열기 | T16: =IF(M16="","",IF(M16=F16,"일치","변경"))
A17: 14 | B17: 여수시 | C17: 12130 | D17: 풍력 | E17: 철도 | F17: 300 | I17: 여수시 도시계획 조례 | J17: 제12조의2 | K17: 가. 도로 및 철도 부지경계에서 직선거리 300미터 이내에 입지하지 아니할 것 | L17: 열기 | T17: =IF(M17="","",IF(M17=F17,"일치","변경"))
A18: 15 | B18: 여수시 | C18: 12130 | D18: 풍력 | E18: 철도 | F18: 200 | I18: 여수시 도시계획 조례 | J18: 제12조의2 | K18: 가. 도로 및 철도, 하천, 저수지 부지경계에서 직선거리 200미터 이내에 입지하지 아니할 것 | L18: 열기 | T18: =IF(M18="","",IF(M18=F18,"일치","변경"))
A19: 16 | B19: 여수시 | C19: 12130 | D19: 풍력 | E19: 철도 | F19: 100 | I19: 여수시 도시계획 조례 | J19: 제12조의2 | K19: 가. 도로 및 철도, 하천, 저수지 부지경계에서 직선거리 100미터 이내에 입지하지 아니할 것 | L19: 열기 | T19: =IF(M19="","",IF(M19=F19,"일치","변경"))
A20: 17 | B20: 여수시 | C20: 12130 | D20: 풍력 | E20: 하천·저수지 | F20: 200 | I20: 여수시 도시계획 조례 | J20: 제12조의2 | K20: 가. 도로 및 철도, 하천, 저수지 부지경계에서 직선거리 200미터 이내에 입지하지 아니할 것 | L20: 열기 | T20: =IF(M20="","",IF(M20=F20,"일치","변경"))
A21: 18 | B21: 여수시 | C21: 12130 | D21: 풍력 | E21: 하천·저수지 | F21: 100 | I21: 여수시 도시계획 조례 | J21: 제12조의2 | K21: 가. 도로 및 철도, 하천, 저수지 부지경계에서 직선거리 100미터 이내에 입지하지 아니할 것 | L21: 열기 | T21: =IF(M21="","",IF(M21=F21,"일치","변경"))
A22: 19 | B22: 여수시 | C22: 12130 | D22: 태양광 | E22: 도로 | F22: 300 | H22: 다만·예외·동의 단서 | I22: 여수시 도시계획 조례 | J22: 제12조의3 | K22: 3. 시설물관리기관(도로, 하천, 구거)에서 유지관리 등에 이상이 없다고 판단하여 점·사용허가를 얻은 경우(다만, 주민이 실제 거주하는 주택의 부지경계로부터 300미터 이상 이격할 것) | L22: 열기 | T22: =IF(M22="","",IF(M22=F22,"일치","변경"))
A23: 20 | B23: 여수시 | C23: 12130 | D23: 태양광 | E23: 도로 | F23: 100 | H23: 다만·예외·동의 단서 | I23: 여수시 도시계획 조례 | J23: 제12조의2 | K23: 가. 도로(왕복 2차로 이상의 포장도로를 말한다. 이하 같다) 및 철도 부지경계에서 직선거리 100미터 이내에 입지하지 아니할 것 (다만, 자연적으로 형성되어 차폐된 지역으로서 도로 가시권 밖에 위치한 경우에는 주변환경 및 경관에 영향을 미치지 아니하는 범위 내에서 예외로 할 수 있다.) | L23: 열기 | T23: =IF(M23="","",IF(M23=F23,"일치","변경"))
A24: 21 | B24: 여수시 | C24: 12130 | D24: 태양광 | E24: 문화유산 | F24: 300 | I24: 여수시 도시계획 조례 | J24: 제12조의2 | K24: 다. 「문화유산법」에 따른 문화재 및 「여수시 문화유산보호관리 조례」에 따른 향토문화유산 부지경계에서 직선거리 300미터 이내에 입지하지 아니할 것<개정 2024. 5. 17.> | L24: 열기 | T24: =IF(M24="","",IF(M24=F24,"일치","변경"))
A25: 22 | B25: 여수시 | C25: 12130 | D25: 태양광 | E25: 주택 | F25: 300 | H25: 다만·예외·동의 단서 | I25: 여수시 도시계획 조례 | J25: 제12조의2 | K25: 나. 주민이 실제 거주하는 주택 부지경계에서 300미터 이내에 입지하지 아니할 것. 다만, 해당 세대주 전체의 동의를 받은 경우에는 예외로 할 수 있다. <단서 신설 2019. 5. 13., 단서 개정 2020. 7. 6.> | L25: 열기 | T25: =IF(M25="","",IF(M25=F25,"일치","변경"))
A26: 23 | B26: 여수시 | C26: 12130 | D26: 태양광 | E26: 주택 | F26: 300 | H26: 다만·예외·동의 단서 | I26: 여수시 도시계획 조례 | J26: 제12조의3 | K26: 3. 시설물관리기관(도로, 하천, 구거)에서 유지관리 등에 이상이 없다고 판단하여 점·사용허가를 얻은 경우(다만, 주민이 실제 거주하는 주택의 부지경계로부터 300미터 이상 이격할 것) | L26: 열기 | T26: =IF(M26="","",IF(M26=F26,"일치","변경"))
A27: 24 | B27: 여수시 | C27: 12130 | D27: 태양광 | E27: 철도 | F27: 100 | H27: 다만·예외·동의 단서 | I27: 여수시 도시계획 조례 | J27: 제12조의2 | K27: 가. 도로(왕복 2차로 이상의 포장도로를 말한다. 이하 같다) 및 철도 부지경계에서 직선거리 100미터 이내에 입지하지 아니할 것 (다만, 자연적으로 형성되어 차폐된 지역으로서 도로 가시권 밖에 위치한 경우에는 주변환경 및 경관에 영향을 미치지 아니하는 범위 내에서 예외로 할 수 있다.) | L27: 열기 | T27: =IF(M27="","",IF(M27=F27,"일치","변경"))
A28: 25 | B28: 여수시 | C28: 12130 | D28: 태양광 | E28: 하천·저수지 | F28: 300 | H28: 다만·예외·동의 단서 | I28: 여수시 도시계획 조례 | J28: 제12조의3 | K28: 3. 시설물관리기관(도로, 하천, 구거)에서 유지관리 등에 이상이 없다고 판단하여 점·사용허가를 얻은 경우(다만, 주민이 실제 거주하는 주택의 부지경계로부터 300미터 이상 이격할 것) | L28: 열기 | T28: =IF(M28="","",IF(M28=F28,"일치","변경"))
A29: 26 | B29: 순천시 | C29: 12150 | D29: 풍력 | E29: 가축사육시설 | F29: 2000 | G29: 5 | I29: 순천시 도시계획 조례 | J29: 제20조의2 | K29: ③ 풍력 발전시설은 도로, 5호 이상 주거 밀집지역, 축사로부터 각각 2,000m 이내에 입지하지 아니하여야 한다. <개정 2019. 6. 10.> | L29: 열기 | T29: =IF(M29="","",IF(M29=F29,"일치","변경"))
A30: 27 | B30: 순천시 | C30: 12150 | D30: 풍력 | E30: 도로 | F30: 2000 | G30: 5 | I30: 순천시 도시계획 조례 | J30: 제20조의2 | K30: ③ 풍력 발전시설은 도로, 5호 이상 주거 밀집지역, 축사로부터 각각 2,000m 이내에 입지하지 아니하여야 한다. <개정 2019. 6. 10.> | L30: 열기 | T30: =IF(M30="","",IF(M30=F30,"일치","변경"))
A31: 28 | B31: 순천시 | C31: 12150 | D31: 풍력 | E31: 주거밀집지역 | F31: 2000 | G31: 5 | I31: 순천시 도시계획 조례 | J31: 제20조의2 | K31: ③ 풍력 발전시설은 도로, 5호 이상 주거 밀집지역, 축사로부터 각각 2,000m 이내에 입지하지 아니하여야 한다. <개정 2019. 6. 10.> | L31: 열기 | T31: =IF(M31="","",IF(M31=F31,"일치","변경"))
A32: 29 | B32: 순천시 | C32: 12150 | D32: 태양광 | E32: 도로 | F32: 200 | I32: 순천시 도시계획 조례 | J32: 제20조의2 | K32: 1. 도로에서 200미터 이내에 입지하지 아니할 것 | L32: 열기 | T32: =IF(M32="","",IF(M32=F32,"일치","변경"))
A33: 30 | B33: 광양시 | C33: 12190 | D33: 풍력 | E33: 가축사육시설 | F33: 2000 | G33: 10 | H33: 한 줄에 거리 여러 개 | I33: 광양시 도시계획 조례 | J33: 제21조의2 | K33: 1. 10호 이상(호간 이격거리 50미터 이내 주택 포함)의 집단 취락지역 경계 주택과 주요 관광지(유원지, 공원 등) 및 공공시설, 축사의 경계로부터 2,000미터 이내에 입지하지 아니할 것(대지를 조성 중이거나 조성이 완료된 대지도 집단 취락지역으로 포함한다) <개정 2025. 12. 31.> | L33: 열기 | T33: =IF(M33="","",IF(M33=F33,"일치","변경"))
A34: 31 | B34: 광양시 | C34: 12190 | D34: 풍력 | E34: 공공시설 | F34: 2000 | G34: 10 | H34: 한 줄에 거리 여러 개 | I34: 광양시 도시계획 조례 | J34: 제21조의2 | K34: 1. 10호 이상(호간 이격거리 50미터 이내 주택 포함)의 집단 취락지역 경계 주택과 주요 관광지(유원지, 공원 등) 및 공공시설, 축사의 경계로부터 2,000미터 이내에 입지하지 아니할 것(대지를 조성 중이거나 조성이 완료된 대지도 집단 취락지역으로 포함한다) <개정 2025. 12. 31.> | L34: 열기 | T34: =IF(M34="","",IF(M34=F34,"일치","변경"))
A35: 32 | B35: 광양시 | C35: 12190 | D35: 풍력 | E35: 공공시설 | F35: 500 | G35: 10 | H35: 한 줄에 거리 여러 개 | I35: 광양시 도시계획 조례 | J35: 제21조의2 | K35: 1. 10호 이상(호간 이격거리 50미터 이내 주택 포함)의 집단 취락지역 경계 주택과 주요 관광지(유원지, 공원 등) 및 공공시설의 경계로부터 500미터 이내에 입지하지 아니할 것(대지를 조성 중이거나 조성이 완료된 대지도 집단취락지역으로 포함한다) <개정 2025. 12. 31.> | L35: 열기 | T35: =IF(M35="","",IF(M35=F35,"일치","변경"))
A36: 33 | B36: 광양시 | C36: 12190 | D36: 풍력 | E36: 관광지 | F36: 2000 | G36: 10 | H36: 한 줄에 거리 여러 개 | I36: 광양시 도시계획 조례 | J36: 제21조의2 | K36: 1. 10호 이상(호간 이격거리 50미터 이내 주택 포함)의 집단 취락지역 경계 주택과 주요 관광지(유원지, 공원 등) 및 공공시설, 축사의 경계로부터 2,000미터 이내에 입지하지 아니할 것(대지를 조성 중이거나 조성이 완료된 대지도 집단 취락지역으로 포함한다) <개정 2025. 12. 31.> | L36: 열기 | T36: =IF(M36="","",IF(M36=F36,"일치","변경"))
A37: 34 | B37: 광양시 | C37: 12190 | D37: 풍력 | E37: 관광지 | F37: 500 | G37: 10 | H37: 한 줄에 거리 여러 개 | I37: 광양시 도시계획 조례 | J37: 제21조의2 | K37: 1. 10호 이상(호간 이격거리 50미터 이내 주택 포함)의 집단 취락지역 경계 주택과 주요 관광지(유원지, 공원 등) 및 공공시설의 경계로부터 500미터 이내에 입지하지 아니할 것(대지를 조성 중이거나 조성이 완료된 대지도 집단취락지역으로 포함한다) <개정 2025. 12. 31.> | L37: 열기 | T37: =IF(M37="","",IF(M37=F37,"일치","변경"))
A38: 35 | B38: 광양시 | C38: 12190 | D38: 풍력 | E38: 도로 | F38: 2000 | I38: 광양시 도시계획 조례 | J38: 제21조의2 | K38: 2. 「도로법」 상 도로 및 철도의 경계로부터 2,000미터 이내에 입지하지 아니할 것(단, 터널 등 지하에 위치하여 가시권에 영향이 없는 경우는 제외한다) <개정 2025. 12. 31.> | L38: 열기 | T38: =IF(M38="","",IF(M38=F38,"일치","변경"))
A39: 36 | B39: 광양시 | C39: 12190 | D39: 풍력 | E39: 도로 | F39: 250 | I39: 광양시 도시계획 조례 | J39: 제21조의2 | K39: 2. 「도로법」 상 국도나 고속국도 경계로부터 250미터 이내에 입지하지 아니할 것 | L39: 열기 | T39: =IF(M39="","",IF(M39=F39,"일치","변경"))
A40: 37 | B40: 광양시 | C40: 12190 | D40: 풍력 | E40: 주거밀집지역 | F40: 2000 | G40: 10 | H40: 한 줄에 거리 여러 개 | I40: 광양시 도시계획 조례 | J40: 제21조의2 | K40: 1. 10호 이상(호간 이격거리 50미터 이내 주택 포함)의 집단 취락지역 경계 주택과 주요 관광지(유원지, 공원 등) 및 공공시설, 축사의 경계로부터 2,000미터 이내에 입지하지 아니할 것(대지를 조성 중이거나 조성이 완료된 대지도 집단 취락지역으로 포함한다) <개정 2025. 12. 31.> | L40: 열기 | T40: =IF(M40="","",IF(M40=F40,"일치","변경"))
...

Sheet 시군별 현황
A1: 시군별 검토 현황
A2: 검토표에 입력하면 자동으로 갱신됩니다
A4: 시군구 | B4: 시군구코드 | C4: 후보 행수 | D4: 검토 완료 (검토자 있음) | E4: 반영(Y) | F4: 진행률 | G4: 비고
A5: 목포시 | B5: 12110 | C5: =COUNTIFS(검토표!$B$4:$B$159,A5) -> 5 | D5: =COUNTIFS(검토표!$B$4:$B$159,A5,검토표!$Q$4:$Q$159,"<>") -> 0 | E5: =COUNTIFS(검토표!$B$4:$B$159,A5,검토표!$P$4:$P$159,"Y") -> 0 | F5: =IF(C5=0,"-",D5/C5) -> 0
A6: 여수시 | B6: 12130 | C6: =COUNTIFS(검토표!$B$4:$B$159,A6) -> 20 | D6: =COUNTIFS(검토표!$B$4:$B$159,A6,검토표!$Q$4:$Q$159,"<>") -> 0 | E6: =COUNTIFS(검토표!$B$4:$B$159,A6,검토표!$P$4:$P$159,"Y") -> 0 | F6: =IF(C6=0,"-",D6/C6) -> 0
A7: 순천시 | B7: 12150 | C7: =COUNTIFS(검토표!$B$4:$B$159,A7) -> 4 | D7: =COUNTIFS(검토표!$B$4:$B$159,A7,검토표!$Q$4:$Q$159,"<>") -> 0 | E7: =COUNTIFS(검토표!$B$4:$B$159,A7,검토표!$P$4:$P$159,"Y") -> 0 | F7: =IF(C7=0,"-",D7/C7) -> 0
A8: 나주시 | B8: 12170 | C8: =COUNTIFS(검토표!$B$4:$B$159,A8) -> 0 | D8: =COUNTIFS(검토표!$B$4:$B$159,A8,검토표!$Q$4:$Q$159,"<>") -> 0 | E8: =COUNTIFS(검토표!$B$4:$B$159,A8,검토표!$P$4:$P$159,"Y") -> 0 | F8: =IF(C8=0,"-",D8/C8) -> - | G8: 조문은 있으나 '요건을 모두 갖춘 경우 허가' 구조라 자동 추출 안 됨
A9: 광양시 | B9: 12190 | C9: =COUNTIFS(검토표!$B$4:$B$159,A9) -> 16 | D9: =COUNTIFS(검토표!$B$4:$B$159,A9,검토표!$Q$4:$Q$159,"<>") -> 0 | E9: =COUNTIFS(검토표!$B$4:$B$159,A9,검토표!$P$4:$P$159,"Y") -> 0 | F9: =IF(C9=0,"-",D9/C9) -> 0
A10: 담양군 | B10: 12710 | C10: =COUNTIFS(검토표!$B$4:$B$159,A10) -> 3 | D10: =COUNTIFS(검토표!$B$4:$B$159,A10,검토표!$Q$4:$Q$159,"<>") -> 0 | E10: =COUNTIFS(검토표!$B$4:$B$159,A10,검토표!$P$4:$P$159,"Y") -> 0 | F10: =IF(C10=0,"-",D10/C10) -> 0
A11: 곡성군 | B11: 12720 | C11: =COUNTIFS(검토표!$B$4:$B$159,A11) -> 4 | D11: =COUNTIFS(검토표!$B$4:$B$159,A11,검토표!$Q$4:$Q$159,"<>") -> 0 | E11: =COUNTIFS(검토표!$B$4:$B$159,A11,검토표!$P$4:$P$159,"Y") -> 0 | F11: =IF(C11=0,"-",D11/C11) -> 0
A12: 구례군 | B12: 12730 | C12: =COUNTIFS(검토표!$B$4:$B$159,A12) -> 10 | D12: =COUNTIFS(검토표!$B$4:$B$159,A12,검토표!$Q$4:$Q$159,"<>") -> 0 | E12: =COUNTIFS(검토표!$B$4:$B$159,A12,검토표!$P$4:$P$159,"Y") -> 0 | F12: =IF(C12=0,"-",D12/C12) -> 0
A13: 고흥군 | B13: 12740 | C13: =COUNTIFS(검토표!$B$4:$B$159,A13) -> 0 | D13: =COUNTIFS(검토표!$B$4:$B$159,A13,검토표!$Q$4:$Q$159,"<>") -> 0 | E13: =COUNTIFS(검토표!$B$4:$B$159,A13,검토표!$P$4:$P$159,"Y") -> 0 | F13: =IF(C13=0,"-",D13/C13) -> - | G13: 이격 조문을 찾지 못함
A14: 보성군 | B14: 12750 | C14: =COUNTIFS(검토표!$B$4:$B$159,A14) -> 12 | D14: =COUNTIFS(검토표!$B$4:$B$159,A14,검토표!$Q$4:$Q$159,"<>") -> 0 | E14: =COUNTIFS(검토표!$B$4:$B$159,A14,검토표!$P$4:$P$159,"Y") -> 0 | F14: =IF(C14=0,"-",D14/C14) -> 0
A15: 화순군 | B15: 12760 | C15: =COUNTIFS(검토표!$B$4:$B$159,A15) -> 12 | D15: =COUNTIFS(검토표!$B$4:$B$159,A15,검토표!$Q$4:$Q$159,"<>") -> 0 | E15: =COUNTIFS(검토표!$B$4:$B$159,A15,검토표!$P$4:$P$159,"Y") -> 0 | F15: =IF(C15=0,"-",D15/C15) -> 0
A16: 장흥군 | B16: 12770 | C16: =COUNTIFS(검토표!$B$4:$B$159,A16) -> 0 | D16: =COUNTIFS(검토표!$B$4:$B$159,A16,검토표!$Q$4:$Q$159,"<>") -> 0 | E16: =COUNTIFS(검토표!$B$4:$B$159,A16,검토표!$P$4:$P$159,"Y") -> 0 | F16: =IF(C16=0,"-",D16/C16) -> - | G16: 이격 조문을 찾지 못함
A17: 강진군 | B17: 12780 | C17: =COUNTIFS(검토표!$B$4:$B$159,A17) -> 0 | D17: =COUNTIFS(검토표!$B$4:$B$159,A17,검토표!$Q$4:$Q$159,"<>") -> 0 | E17: =COUNTIFS(검토표!$B$4:$B$159,A17,검토표!$P$4:$P$159,"Y") -> 0 | F17: =IF(C17=0,"-",D17/C17) -> - | G17: 이격 조문을 찾지 못함
A18: 해남군 | B18: 12790 | C18: =COUNTIFS(검토표!$B$4:$B$159,A18) -> 12 | D18: =COUNTIFS(검토표!$B$4:$B$159,A18,검토표!$Q$4:$Q$159,"<>") -> 0 | E18: =COUNTIFS(검토표!$B$4:$B$159,A18,검토표!$P$4:$P$159,"Y") -> 0 | F18: =IF(C18=0,"-",D18/C18) -> 0
A19: 영암군 | B19: 12800 | C19: =COUNTIFS(검토표!$B$4:$B$159,A19) -> 2 | D19: =COUNTIFS(검토표!$B$4:$B$159,A19,검토표!$Q$4:$Q$159,"<>") -> 0 | E19: =COUNTIFS(검토표!$B$4:$B$159,A19,검토표!$P$4:$P$159,"Y") -> 0 | F19: =IF(C19=0,"-",D19/C19) -> 0
A20: 무안군 | B20: 12810 | C20: =COUNTIFS(검토표!$B$4:$B$159,A20) -> 12 | D20: =COUNTIFS(검토표!$B$4:$B$159,A20,검토표!$Q$4:$Q$159,"<>") -> 0 | E20: =COUNTIFS(검토표!$B$4:$B$159,A20,검토표!$P$4:$P$159,"Y") -> 0 | F20: =IF(C20=0,"-",D20/C20) -> 0
A21: 함평군 | B21: 12820 | C21: =COUNTIFS(검토표!$B$4:$B$159,A21) -> 6 | D21: =COUNTIFS(검토표!$B$4:$B$159,A21,검토표!$Q$4:$Q$159,"<>") -> 0 | E21: =COUNTIFS(검토표!$B$4:$B$159,A21,검토표!$P$4:$P$159,"Y") -> 0 | F21: =IF(C21=0,"-",D21/C21) -> 0
A22: 영광군 | B22: 12830 | C22: =COUNTIFS(검토표!$B$4:$B$159,A22) -> 0 | D22: =COUNTIFS(검토표!$B$4:$B$159,A22,검토표!$Q$4:$Q$159,"<>") -> 0 | E22: =COUNTIFS(검토표!$B$4:$B$159,A22,검토표!$P$4:$P$159,"Y") -> 0 | F22: =IF(C22=0,"-",D22/C22) -> - | G22: 이격 조문을 찾지 못함
A23: 장성군 | B23: 12840 | C23: =COUNTIFS(검토표!$B$4:$B$159,A23) -> 8 | D23: =COUNTIFS(검토표!$B$4:$B$159,A23,검토표!$Q$4:$Q$159,"<>") -> 0 | E23: =COUNTIFS(검토표!$B$4:$B$159,A23,검토표!$P$4:$P$159,"Y") -> 0 | F23: =IF(C23=0,"-",D23/C23) -> 0
A24: 완도군 | B24: 12850 | C24: =COUNTIFS(검토표!$B$4:$B$159,A24) -> 9 | D24: =COUNTIFS(검토표!$B$4:$B$159,A24,검토표!$Q$4:$Q$159,"<>") -> 0 | E24: =COUNTIFS(검토표!$B$4:$B$159,A24,검토표!$P$4:$P$159,"Y") -> 0 | F24: =IF(C24=0,"-",D24/C24) -> 0
A25: 진도군 | B25: 12860 | C25: =COUNTIFS(검토표!$B$4:$B$159,A25) -> 14 | D25: =COUNTIFS(검토표!$B$4:$B$159,A25,검토표!$Q$4:$Q$159,"<>") -> 0 | E25: =COUNTIFS(검토표!$B$4:$B$159,A25,검토표!$P$4:$P$159,"Y") -> 0 | F25: =IF(C25=0,"-",D25/C25) -> 0
A26: 신안군 | B26: 12870 | C26: =COUNTIFS(검토표!$B$4:$B$159,A26) -> 7 | D26: =COUNTIFS(검토표!$B$4:$B$159,A26,검토표!$Q$4:$Q$159,"<>") -> 0 | E26: =COUNTIFS(검토표!$B$4:$B$159,A26,검토표!$P$4:$P$159,"Y") -> 0 | F26: =IF(C26=0,"-",D26/C26) -> 0
A27: 합계 | C27: =SUM(C5:C26) -> 156 | D27: =SUM(D5:D26) -> 0 | E27: =SUM(E5:E26) -> 0 | F27: =IF(C27=0,"-",D27/C27) -> 0

Sheet 직접 확인 필요
A1: 직접 확인 필요 (5개 시군)
A2: 자동 추출이 안 된 시군입니다. 조례 전문을 열어 이격 규정이 있는지 확인하고, 있으면 검토표 맨 아래에 행을 추가해 주세요. 규정이 '없다'고 확인되면 그 사실도 판정에 쓰입니다(→ 비저촉).
A4: 시군구 | B4: 시군구코드 | C4: 사유 | D4: 수집된 조문 (앞부분) | E4: 조례 전문
A5: 나주시 | B5: 12170 | C5: 조문은 있으나 '요건을 모두 갖춘 경우 허가' 구조라 자동 추출 안 됨 | D5: 제24조(개발행위허가의 기준) ① 개발행위 허가를 하고자 하는 지역 또는 주변지역이 다음 각 호의 어느 하나에 해당되는 경우에는 개발행위로 인하여 해당 지역 또는 그 주변 지역에 환경오염, 생태계파괴, 위해발생 등이 예상되므로 환경오염의 방지, 조경, 녹지의 조성, 완충지대의 설치 등 필요한 조치를 조건으로 하는 경우 외에는 개발행위허가를 하여서는 아니 된다. 1. 보호수의 보존에 필요한 지역 2. 「자연환경보전법」 제2조에 따른 멸종위기 야생동ㆍ식물, 보호생동ㆍ식물, 국제적 멸종위기 등이 서식 또는 자생하고 있거나 다양한 생물종이 풍부한 습지 등과 연결되어 생태보전이 필요한 지역 3. 녹지지역 또는 계획관리지역으로서 수목의 집단 생육지역, 조수류 등의 집단 서식지역 또는 우량농지 등으로 보전할 필요가 있는 지역 4. 개발행위로 인하여 주변의 환경ㆍ경관ㆍ미관ㆍ문화재 등이 크게 오염 손상될 우려가 있는 지역 5. 도시기본계획 또는 도시관리계획이 수립중인 지역으로써 용도지역ㆍ지구ㆍ구역 변경이 예상되고 그에 따라 개발행위허가 기준이 크게 달라질 것으로 예상 되는 지역 ② 영 제56조의 별표 1의2 제1호가목에 따라 시장은 다음 각 호의 요건을 모두 갖춘 행위에 … | E5: 열기
A6: 고흥군 | B6: 12740 | C6: 이격 조문을 찾지 못함 | D6: (자동수집 실패 - 조례 전문에서 '이격' 언급 조문 없음) | E6: 링크 없음
A7: 장흥군 | B7: 12770 | C7: 이격 조문을 찾지 못함 | D7: (자동수집 실패 - 조례 전문에서 '이격' 언급 조문 없음) | E7: 링크 없음
A8: 강진군 | B8: 12780 | C8: 이격 조문을 찾지 못함 | D8: (자동수집 실패 - 조례 전문에서 '이격' 언급 조문 없음) | E8: 링크 없음
A9: 영광군 | B9: 12830 | C9: 이격 조문을 찾지 못함 | D9: (자동수집 실패 - 조례 전문에서 '이격' 언급 조문 없음) | E9: 링크 없음
